<sdf version='1.10'>
  <world name='iris_runway'>
    <physics name='1ms' type='ignore'>
      <max_step_size>0.001</max_step_size>
      <real_time_factor>1</real_time_factor>
      <real_time_update_rate>1000</real_time_update_rate>
    </physics>
    <plugin name='gz::sim::systems::Physics' filename='gz-sim-physics-system'/>
    <plugin name='gz::sim::systems::Sensors' filename='gz-sim-sensors-system'>
      <render_engine>ogre2</render_engine>
    </plugin>
    <plugin name='gz::sim::systems::UserCommands' filename='gz-sim-user-commands-system'/>
    <plugin name='gz::sim::systems::SceneBroadcaster' filename='gz-sim-scene-broadcaster-system'/>
    <plugin name='gz::sim::systems::Imu' filename='gz-sim-imu-system'/>
    <plugin name='gz::sim::systems::NavSat' filename='gz-sim-navsat-system'/>
    <scene>
      <ambient>1 1 1 1</ambient>
      <background>0.800000012 0.800000012 0.800000012 1</background>
      <sky/>
      <shadows>true</shadows>
    </scene>
    <spherical_coordinates>
      <latitude_deg>-35.363261999999999</latitude_deg>
      <longitude_deg>149.16523699999999</longitude_deg>
      <elevation>584</elevation>
      <heading_deg>0</heading_deg>
      <surface_model>EARTH_WGS84</surface_model>
    </spherical_coordinates>
    <gravity>0 0 -9.8000000000000007</gravity>
    <magnetic_field>5.5644999999999998e-06 2.2875799999999999e-05 -4.2388400000000002e-05</magnetic_field>
    <atmosphere type='adiabatic'/>
    <model name='axes'>
      <static>true</static>
      <link name='link'>
        <visual name='r'>
          <cast_shadows>false</cast_shadows>
          <pose>5 0 0.10000000000000001 0 0 0</pose>
          <geometry>
            <box>
              <size>10 0.01 0.01</size>
            </box>
          </geometry>
          <material>
            <ambient>1 0 0 0.800000012</ambient>
            <diffuse>1 0 0 0.800000012</diffuse>
            <emissive>1 0 0 0.800000012</emissive>
            <specular>0.5 0.5 0.5 0.800000012</specular>
          </material>
        </visual>
        <visual name='g'>
          <cast_shadows>false</cast_shadows>
          <pose>0 5 0.10000000000000001 0 0 0</pose>
          <geometry>
            <box>
              <size>0.01 10 0.01</size>
            </box>
          </geometry>
          <material>
            <ambient>0 1 0 0.800000012</ambient>
            <diffuse>0 1 0 0.800000012</diffuse>
            <emissive>0 1 0 0.800000012</emissive>
            <specular>0.5 0.5 0.5 0.800000012</specular>
          </material>
        </visual>
        <visual name='b'>
          <cast_shadows>false</cast_shadows>
          <pose>0 0 5.0999999999999996 0 0 0</pose>
          <geometry>
            <box>
              <size>0.01 0.01 10</size>
            </box>
          </geometry>
          <material>
            <ambient>0 0 1 0.800000012</ambient>
            <diffuse>0 0 1 0.800000012</diffuse>
            <emissive>0 0 1 0.800000012</emissive>
            <specular>0.5 0.5 0.5 0.800000012</specular>
          </material>
        </visual>
        <sensor name='navsat_sensor' type='navsat'>
          <always_on>true</always_on>
          <update_rate>1</update_rate>
          <gps/>
        </sensor>
        <pose>0 0 0 0 0 0</pose>
        <inertial>
          <pose>0 0 0 0 0 0</pose>
          <mass>1</mass>
          <inertia>
            <ixx>1</ixx>
            <ixy>0</ixy>
            <ixz>0</ixz>
            <iyy>1</iyy>
            <iyz>0</iyz>
            <izz>1</izz>
          </inertia>
        </inertial>
        <enable_wind>false</enable_wind>
      </link>
      <pose>0 0 0 0 0 0</pose>
      <self_collide>false</self_collide>
    </model>
    <model name='runway'>
      <static>true</static>
      <link name='link'>
        <collision name='collision'>
          <geometry>
            <plane>
              <normal>0 0 1</normal>
              <size>1 1</size>
            </plane>
          </geometry>
          <surface>
            <friction>
              <ode/>
            </friction>
            <bounce/>
            <contact/>
          </surface>
        </collision>
        <visual name='runway'>
          <pose degrees='true'>0 0 0   0 0 89.999999999999986</pose>
          <cast_shadows>false</cast_shadows>
          <geometry>
            <plane>
              <normal>0 0 1</normal>
              <size>1500 100</size>
            </plane>
          </geometry>
          <material>
            <ambient>0.800000012 0.800000012 0.800000012 1</ambient>
            <diffuse>0.800000012 0.800000012 0.800000012 1</diffuse>
            <specular>0.100000001 0.100000001 0.100000001 1</specular>
            <pbr>
              <metal>
                <albedo_map>materials/textures/runway.png</albedo_map>
                <roughness>0.6</roughness>
                <metalness>0</metalness>
              </metal>
            </pbr>
          </material>
        </visual>
        <visual name='airfield'>
          <pose>0 0 -0.01 0 0 0</pose>
          <cast_shadows>false</cast_shadows>
          <geometry>
            <mesh>
              <uri>file:///home/aryan/ardupilot_gazebo/models/runway/model://runway/meshes/airfield.dae</uri>
            </mesh>
          </geometry>
          <material>
            <ambient>0.800000012 0.800000012 0.800000012 1</ambient>
            <diffuse>0.800000012 0.800000012 0.800000012 1</diffuse>
            <specular>0.100000001 0.100000001 0.100000001 1</specular>
            <pbr>
              <metal>
                <albedo_map>materials/textures/Grass004_2K_Color.jpg</albedo_map>
                <ambient_occlusion_map>materials/textures/Grass004_2K_AmbientOcclusion.jpg</ambient_occlusion_map>
                <normal_map>materials/textures/Grass004_2K_NormalGL.jpg</normal_map>
                <roughness_map>materials/textures/Grass004_2K_Roughness.jpg</roughness_map>
                <roughness>0.6</roughness>
                <metalness>0</metalness>
              </metal>
            </pbr>
          </material>
        </visual>
        <pose>0 0 0 0 0 0</pose>
        <inertial>
          <pose>0 0 0 0 0 0</pose>
          <mass>1</mass>
          <inertia>
            <ixx>1</ixx>
            <ixy>0</ixy>
            <ixz>0</ixz>
            <iyy>1</iyy>
            <iyz>0</iyz>
            <izz>1</izz>
          </inertia>
        </inertial>
        <enable_wind>false</enable_wind>
      </link>
      <pose>-29 545 0 0 0 0.052359877559829945</pose>
      <self_collide>false</self_collide>
    </model>
    <model name='iris_with_gimbal_9002'>
      <model name='iris_with_standoffs'>
        <pose>0 0 0 0 0 0</pose>
        <link name='base_link'>
          <velocity_decay>
            <linear>0</linear>
            <angular>0</angular>
          </velocity_decay>
          <inertial>
            <pose>0 0 0 0 0 0</pose>
            <mass>1.5</mass>
            <inertia>
              <ixx>0.0080000000000000002</ixx>
              <ixy>0</ixy>
              <ixz>0</ixz>
              <iyy>0.014999999999999999</iyy>
              <iyz>0</iyz>
              <izz>0.017000000000000001</izz>
            </inertia>
          </inertial>
          <collision name='base_collision'>
            <pose>0 0 -0.080000000000000002 0 0 0</pose>
            <geometry>
              <box>
                <size>0.46999999999999997 0.46999999999999997 0.23000000000000001</size>
              </box>
            </geometry>
            <surface>
              <contact>
                <ode>
                  <max_vel>100</max_vel>
                  <min_depth>0.001</min_depth>
                </ode>
              </contact>
              <friction>
                <ode>
                  <mu>100000</mu>
                  <mu2>100000</mu2>
                </ode>
              </friction>
              <bounce/>
            </surface>
          </collision>
          <visual name='base_visual'>
            <geometry>
              <mesh>
                <uri>model://iris_with_standoffs/meshes/iris.dae</uri>
              </mesh>
            </geometry>
            <material>
              <ambient>0.0500000007 0.0500000007 0.0500000007 1</ambient>
              <diffuse>0.0500000007 0.0500000007 0.0500000007 1</diffuse>
              <specular>1 1 1 1</specular>
              <pbr>
                <metal>
                  <metalness>0.5</metalness>
                  <roughness>0.5</roughness>
                </metal>
              </pbr>
            </material>
          </visual>
          <visual name='front_left_leg_visual'>
            <pose>0.123 0.22 -0.11 0 0 0</pose>
            <geometry>
              <cylinder>
                <radius>0.0050000000000000001</radius>
                <length>0.17000000000000001</length>
              </cylinder>
            </geometry>
            <material>
              <ambient>0.0500000007 0.0500000007 0.0500000007 1</ambient>
              <diffuse>0.0500000007 0.0500000007 0.0500000007 1</diffuse>
              <specular>0.00999999978 0.00999999978 0.00999999978 1</specular>
              <pbr>
                <metal>
                  <metalness>0.5</metalness>
                  <roughness>0.5</roughness>
                </metal>
              </pbr>
            </material>
          </visual>
          <visual name='front_right_leg_visual'>
            <pose>0.123 -0.22 -0.11 0 0 0</pose>
            <geometry>
              <cylinder>
                <radius>0.0050000000000000001</radius>
                <length>0.17000000000000001</length>
              </cylinder>
            </geometry>
            <material>
              <ambient>0.0500000007 0.0500000007 0.0500000007 1</ambient>
              <diffuse>0.0500000007 0.0500000007 0.0500000007 1</diffuse>
              <specular>0.00999999978 0.00999999978 0.00999999978 1</specular>
              <pbr>
                <metal>
                  <metalness>0.5</metalness>
                  <roughness>0.5</roughness>
                </metal>
              </pbr>
            </material>
          </visual>
          <visual name='rear_left_leg_visual'>
            <pose>-0.14000000000000001 0.20999999999999999 -0.11 0 0 0</pose>
            <geometry>
              <cylinder>
                <radius>0.0050000000000000001</radius>
                <length>0.17000000000000001</length>
              </cylinder>
            </geometry>
            <material>
              <ambient>0.0500000007 0.0500000007 0.0500000007 1</ambient>
              <diffuse>0.0500000007 0.0500000007 0.0500000007 1</diffuse>
              <specular>0.00999999978 0.00999999978 0.00999999978 1</specular>
              <pbr>
                <metal>
                  <metalness>0.5</metalness>
                  <roughness>0.5</roughness>
                </metal>
              </pbr>
            </material>
          </visual>
          <visual name='rear_right_leg_visual'>
            <pose>-0.14000000000000001 -0.20999999999999999 -0.11 0 0 0</pose>
            <geometry>
              <cylinder>
                <radius>0.0050000000000000001</radius>
                <length>0.17000000000000001</length>
              </cylinder>
            </geometry>
            <material>
              <ambient>0.0500000007 0.0500000007 0.0500000007 1</ambient>
              <diffuse>0.0500000007 0.0500000007 0.0500000007 1</diffuse>
              <specular>0.00999999978 0.00999999978 0.00999999978 1</specular>
              <pbr>
                <metal>
                  <metalness>0.5</metalness>
                  <roughness>0.5</roughness>
                </metal>
              </pbr>
            </material>
          </visual>
        </link>
        <link name='imu_link'>
          <inertial>
            <pose>0 0 0 0 0 0</pose>
            <mass>0.14999999999999999</mass>
            <inertia>
              <ixx>1.0000000000000001e-05</ixx>
              <ixy>0</ixy>
              <ixz>0</ixz>
              <iyy>2.0000000000000002e-05</iyy>
              <iyz>0</iyz>
              <izz>2.0000000000000002e-05</izz>
            </inertia>
          </inertial>
          <sensor name='imu_sensor' type='imu'>
            <pose degrees='true'>0 0 0   180 0 0</pose>
            <always_on>true</always_on>
            <update_rate>1000</update_rate>
            <imu/>
          </sensor>
        </link>
        <joint name='imu_joint' type='revolute'>
          <child>imu_link</child>
          <parent>base_link</parent>
          <axis>
            <xyz>0 0 1</xyz>
            <limit>
              <lower>0</lower>
              <upper>0</upper>
              <effort>0</effort>
              <velocity>0</velocity>
            </limit>
            <dynamics>
              <damping>1</damping>
              <spring_reference>0</spring_reference>
              <spring_stiffness>0</spring_stiffness>
            </dynamics>
          </axis>
        </joint>
        <link name='rotor_0'>
          <pose>0.13 -0.22 0.023 0 0 0</pose>
          <inertial>
            <pose>0 0 0 0 0 0</pose>
            <mass>0.025000000000000001</mass>
            <inertia>
              <ixx>9.7499999999999998e-06</ixx>
              <ixy>0</ixy>
              <ixz>0</ixz>
              <iyy>0.00016670399999999999</iyy>
              <iyz>0</iyz>
              <izz>0.00016760399999999999</izz>
            </inertia>
          </inertial>
          <collision name='rotor_0_collision'>
            <pose>0 0 0 0 0 0</pose>
            <geometry>
              <cylinder>
                <length>0.0050000000000000001</length>
                <radius>0.10000000000000001</radius>
              </cylinder>
            </geometry>
            <surface>
              <contact>
                <ode/>
              </contact>
              <friction>
                <ode/>
              </friction>
              <bounce/>
            </surface>
          </collision>
          <visual name='rotor_0_visual'>
            <pose>0 0 0 0 0 0</pose>
            <geometry>
              <mesh>
                <scale>1 1 1</scale>
                <uri>model://iris_with_standoffs/meshes/iris_prop_ccw.dae</uri>
              </mesh>
            </geometry>
            <material>
              <ambient>0 0 1 1</ambient>
              <diffuse>0 0 1 1</diffuse>
              <specular>1 1 1 1</specular>
              <pbr>
                <metal>
                  <metalness>0.5</metalness>
                  <roughness>0.5</roughness>
                </metal>
              </pbr>
            </material>
          </visual>
          <gravity>true</gravity>
          <velocity_decay/>
          <self_collide>false</self_collide>
        </link>
        <joint name='rotor_0_joint' type='revolute'>
          <child>rotor_0</child>
          <parent>base_link</parent>
          <axis>
            <xyz>0 0 1</xyz>
            <limit>
              <lower>-10000000000000000</lower>
              <upper>10000000000000000</upper>
            </limit>
            <dynamics>
              <damping>0.0040000000000000001</damping>
              <spring_reference>0</spring_reference>
              <spring_stiffness>0</spring_stiffness>
            </dynamics>
          </axis>
          <physics>
            <ode>
              <implicit_spring_damper>true</implicit_spring_damper>
            </ode>
          </physics>
        </joint>
        <link name='rotor_1'>
          <pose>-0.13 0.20000000000000001 0.023 0 0 0</pose>
          <inertial>
            <pose>0 0 0 0 0 0</pose>
            <mass>0.025000000000000001</mass>
            <inertia>
              <ixx>9.7499999999999998e-06</ixx>
              <ixy>0</ixy>
              <ixz>0</ixz>
              <iyy>0.00016670399999999999</iyy>
              <iyz>0</iyz>
              <izz>0.00016760399999999999</izz>
            </inertia>
          </inertial>
          <collision name='rotor_1_collision'>
            <pose>0 0 0 0 0 0</pose>
            <geometry>
              <cylinder>
                <length>0.0050000000000000001</length>
                <radius>0.10000000000000001</radius>
              </cylinder>
            </geometry>
            <surface>
              <contact>
                <ode/>
              </contact>
              <friction>
                <ode/>
              </friction>
              <bounce/>
            </surface>
          </collision>
          <visual name='rotor_1_visual'>
            <pose>0 0 0 0 0 0</pose>
            <geometry>
              <mesh>
                <scale>1 1 1</scale>
                <uri>model://iris_with_standoffs/meshes/iris_prop_ccw.dae</uri>
              </mesh>
            </geometry>
            <material>
              <ambient>0 0 1 1</ambient>
              <diffuse>0 0 1 1</diffuse>
              <specular>1 1 1 1</specular>
              <pbr>
                <metal>
                  <metalness>0.5</metalness>
                  <roughness>0.5</roughness>
                </metal>
              </pbr>
            </material>
          </visual>
          <gravity>true</gravity>
          <velocity_decay/>
          <self_collide>false</self_collide>
        </link>
        <joint name='rotor_1_joint' type='revolute'>
          <child>rotor_1</child>
          <parent>base_link</parent>
          <axis>
            <xyz>0 0 1</xyz>
            <limit>
              <lower>-10000000000000000</lower>
              <upper>10000000000000000</upper>
            </limit>
            <dynamics>
              <damping>0.0040000000000000001</damping>
              <spring_reference>0</spring_reference>
              <spring_stiffness>0</spring_stiffness>
            </dynamics>
          </axis>
          <physics>
            <ode>
              <implicit_spring_damper>true</implicit_spring_damper>
            </ode>
          </physics>
        </joint>
        <link name='rotor_2'>
          <pose>0.13 0.22 0.023 0 0 0</pose>
          <inertial>
            <pose>0 0 0 0 0 0</pose>
            <mass>0.025000000000000001</mass>
            <inertia>
              <ixx>9.7499999999999998e-06</ixx>
              <ixy>0</ixy>
              <ixz>0</ixz>
              <iyy>0.00016670399999999999</iyy>
              <iyz>0</iyz>
              <izz>0.00016760399999999999</izz>
            </inertia>
          </inertial>
          <collision name='rotor_2_collision'>
            <pose>0 0 0 0 0 0</pose>
            <geometry>
              <cylinder>
                <length>0.0050000000000000001</length>
                <radius>0.10000000000000001</radius>
              </cylinder>
            </geometry>
            <surface>
              <contact>
                <ode/>
              </contact>
              <friction>
                <ode/>
              </friction>
              <bounce/>
            </surface>
          </collision>
          <visual name='rotor_2_visual'>
            <pose>0 0 0 0 0 0</pose>
            <geometry>
              <mesh>
                <scale>1 1 1</scale>
                <uri>model://iris_with_standoffs/meshes/iris_prop_cw.dae</uri>
              </mesh>
            </geometry>
            <material>
              <ambient>0 1 0 1</ambient>
              <diffuse>0 1 0 1</diffuse>
              <specular>1 1 1 1</specular>
              <pbr>
                <metal>
                  <metalness>0.5</metalness>
                  <roughness>0.5</roughness>
                </metal>
              </pbr>
            </material>
          </visual>
          <gravity>true</gravity>
          <velocity_decay/>
          <self_collide>false</self_collide>
        </link>
        <joint name='rotor_2_joint' type='revolute'>
          <child>rotor_2</child>
          <parent>base_link</parent>
          <axis>
            <xyz>0 0 1</xyz>
            <limit>
              <lower>-10000000000000000</lower>
              <upper>10000000000000000</upper>
            </limit>
            <dynamics>
              <damping>0.0040000000000000001</damping>
              <spring_reference>0</spring_reference>
              <spring_stiffness>0</spring_stiffness>
            </dynamics>
          </axis>
          <physics>
            <ode>
              <implicit_spring_damper>true</implicit_spring_damper>
            </ode>
          </physics>
        </joint>
        <link name='rotor_3'>
          <pose>-0.13 -0.20000000000000001 0.023 0 0 0</pose>
          <inertial>
            <pose>0 0 0 0 0 0</pose>
            <mass>0.025000000000000001</mass>
            <inertia>
              <ixx>9.7499999999999998e-06</ixx>
              <ixy>0</ixy>
              <ixz>0</ixz>
              <iyy>0.00016670399999999999</iyy>
              <iyz>0</iyz>
              <izz>0.00016760399999999999</izz>
            </inertia>
          </inertial>
          <collision name='rotor_3_collision'>
            <pose>0 0 0 0 0 0</pose>
            <geometry>
              <cylinder>
                <length>0.0050000000000000001</length>
                <radius>0.10000000000000001</radius>
              </cylinder>
            </geometry>
            <surface>
              <contact>
                <ode/>
              </contact>
              <friction>
                <ode/>
              </friction>
              <bounce/>
            </surface>
          </collision>
          <visual name='rotor_3_visual'>
            <pose>0 0 0 0 0 0</pose>
            <geometry>
              <mesh>
                <scale>1 1 1</scale>
                <uri>model://iris_with_standoffs/meshes/iris_prop_cw.dae</uri>
              </mesh>
            </geometry>
            <material>
              <ambient>0 1 0 1</ambient>
              <diffuse>0 1 0 1</diffuse>
              <specular>1 1 1 1</specular>
              <pbr>
                <metal>
                  <metalness>0.5</metalness>
                  <roughness>0.5</roughness>
                </metal>
              </pbr>
            </material>
          </visual>
          <gravity>true</gravity>
          <velocity_decay/>
          <self_collide>false</self_collide>
        </link>
        <joint name='rotor_3_joint' type='revolute'>
          <child>rotor_3</child>
          <parent>base_link</parent>
          <axis>
            <xyz>0 0 1</xyz>
            <limit>
              <lower>-10000000000000000</lower>
              <upper>10000000000000000</upper>
            </limit>
            <dynamics>
              <damping>0.0040000000000000001</damping>
              <spring_reference>0</spring_reference>
              <spring_stiffness>0</spring_stiffness>
            </dynamics>
          </axis>
          <physics>
            <ode>
              <implicit_spring_damper>true</implicit_spring_damper>
            </ode>
          </physics>
        </joint>
      </model>
      <model name='gimbal'>
        <pose degrees='true'>0 -0.01 -0.12492300000000001   89.999999999999986 0 89.999999999999986</pose>
        <link name='base_link'>
          <inertial>
            <mass>0.20000000000000001</mass>
            <inertia>
              <ixx>0.0001</ixx>
              <ixy>0</ixy>
              <ixz>0</ixz>
              <iyy>0.0001</iyy>
              <iyz>0</iyz>
              <izz>0.0001</izz>
            </inertia>
          </inertial>
          <visual name='base_visual'>
            <geometry>
              <mesh>
                <uri>model://gimbal_small_3d/meshes/base_plate.dae</uri>
              </mesh>
            </geometry>
            <material>
              <ambient>0.100000001 0.100000001 0.100000001 1</ambient>
              <diffuse>0.100000001 0.100000001 0.100000001 1</diffuse>
              <specular>0.00999999978 0.00999999978 0.00999999978 1</specular>
            </material>
          </visual>
          <collision name='base_collision'>
            <pose>0.01 0.074999999999999997 -0.025000000000000001 0 0 0</pose>
            <geometry>
              <box>
                <size>0.10000000000000001 0.050000000000000003 0.14999999999999999</size>
              </box>
            </geometry>
            <surface>
              <friction>
                <ode/>
              </friction>
              <bounce/>
              <contact/>
            </surface>
          </collision>
        </link>
        <link name='yaw_link'>
          <inertial>
            <mass>0.01</mass>
            <inertia>
              <ixx>1.0000000000000001e-05</ixx>
              <ixy>0</ixy>
              <ixz>0</ixz>
              <iyy>1.0000000000000001e-05</iyy>
              <iyz>0</iyz>
              <izz>1.0000000000000001e-05</izz>
            </inertia>
          </inertial>
          <visual name='yaw_visual'>
            <geometry>
              <mesh>
                <uri>model://gimbal_small_3d/meshes/yaw_arm.dae</uri>
              </mesh>
            </geometry>
            <material>
              <ambient>0.100000001 0.100000001 0.100000001 1</ambient>
              <diffuse>0.100000001 0.100000001 0.100000001 1</diffuse>
              <specular>0.00999999978 0.00999999978 0.00999999978 1</specular>
            </material>
          </visual>
          <collision name='yaw_collision'>
            <geometry>
              <mesh>
                <uri>model://gimbal_small_3d/meshes/yaw_arm.dae</uri>
              </mesh>
            </geometry>
          </collision>
        </link>
        <joint name='yaw_joint' type='revolute'>
          <parent>base_link</parent>
          <child>yaw_link</child>
          <axis>
            <xyz>0 1 0</xyz>
            <dynamics>
              <damping>0.01</damping>
              <spring_reference>0</spring_reference>
              <spring_stiffness>0</spring_stiffness>
            </dynamics>
            <limit>
              <lower>-3.1415926000000001</lower>
              <upper>3.1415926000000001</upper>
            </limit>
          </axis>
          <pose>0.010500000000000001 0.065000000000000002 -0.002 0 0 0</pose>
        </joint>
        <link name='roll_link'>
          <inertial>
            <mass>0.01</mass>
            <inertia>
              <ixx>1.0000000000000001e-05</ixx>
              <ixy>0</ixy>
              <ixz>0</ixz>
              <iyy>1.0000000000000001e-05</iyy>
              <iyz>0</iyz>
              <izz>1.0000000000000001e-05</izz>
            </inertia>
          </inertial>
          <visual name='roll_visual'>
            <geometry>
              <mesh>
                <uri>model://gimbal_small_3d/meshes/roll_arm.dae</uri>
              </mesh>
            </geometry>
            <material>
              <ambient>0.100000001 0.100000001 0.100000001 1</ambient>
              <diffuse>0.100000001 0.100000001 0.100000001 1</diffuse>
              <specular>0.00999999978 0.00999999978 0.00999999978 1</specular>
            </material>
          </visual>
          <collision name='roll_collision'>
            <geometry>
              <mesh>
                <uri>model://gimbal_small_3d/meshes/roll_arm.dae</uri>
              </mesh>
            </geometry>
          </collision>
        </link>
        <joint name='roll_joint' type='revolute'>
          <parent>yaw_link</parent>
          <child>roll_link</child>
          <axis>
            <xyz>0 0 1</xyz>
            <dynamics>
              <damping>0.01</damping>
              <spring_reference>0</spring_reference>
              <spring_stiffness>0</spring_stiffness>
            </dynamics>
            <limit>
              <lower>-3.1415926000000001</lower>
              <upper>3.1415926000000001</upper>
            </limit>
          </axis>
          <pose>0.0099000000000000008 0.002 -0.050000000000000003 0 0 0</pose>
        </joint>
        <link name='pitch_link'>
          <inertial>
            <mass>0.01</mass>
            <inertia>
              <ixx>1.0000000000000001e-05</ixx>
              <ixy>0</ixy>
              <ixz>0</ixz>
              <iyy>1.0000000000000001e-05</iyy>
              <iyz>0</iyz>
              <izz>1.0000000000000001e-05</izz>
            </inertia>
          </inertial>
          <visual name='pitch_visual'>
            <pose>0 0 0 0 0 0</pose>
            <geometry>
              <mesh>
                <uri>model://gimbal_small_3d/meshes/camera_enclosure.dae</uri>
              </mesh>
            </geometry>
            <material>
              <ambient>0.400000006 0.400000006 0.400000006 1</ambient>
              <diffuse>0.400000006 0.400000006 0.400000006 1</diffuse>
              <specular>0.100000001 0.100000001 0.100000001 1</specular>
            </material>
          </visual>
          <collision name='pitch_collision'>
            <pose>0 0 0 0 0 0</pose>
            <geometry>
              <mesh>
                <uri>model://gimbal_small_3d/meshes/camera_enclosure.dae</uri>
              </mesh>
            </geometry>
          </collision>
          <visual name='camera_visual'>
            <pose>0 0 0.02 0 0 0</pose>
            <geometry>
              <cylinder>
                <radius>0.025000000000000001</radius>
                <length>0.050000000000000003</length>
              </cylinder>
            </geometry>
            <material>
              <ambient>0.400000006 0.400000006 0.400000006 1</ambient>
              <diffuse>0.400000006 0.400000006 0.400000006 1</diffuse>
              <specular>0.100000001 0.100000001 0.100000001 1</specular>
            </material>
          </visual>
          <collision name='camera_collision'>
            <pose>0 0 0.02 0 0 0</pose>
            <geometry>
              <cylinder>
                <radius>0.025000000000000001</radius>
                <length>0.050000000000000003</length>
              </cylinder>
            </geometry>
            <surface>
              <friction>
                <ode/>
              </friction>
              <bounce/>
              <contact/>
            </surface>
          </collision>
          <sensor name='camera' type='camera'>
            <pose>0 0 0 -1.5700000000001126 -1.5700000000001271 6.9709015763319957e-14</pose>
            <camera>
              <horizontal_fov>2</horizontal_fov>
              <image>
                <width>640</width>
                <height>480</height>
              </image>
              <clip>
                <near>0.050000000000000003</near>
                <far>15000</far>
              </clip>
            </camera>
            <always_on>true</always_on>
            <update_rate>10</update_rate>
            <visualize>true</visualize>
            <plugin name='CameraZoomPlugin' filename='CameraZoomPlugin'>
              <max_zoom>125.0</max_zoom>
              <slew_rate>0.42514285714</slew_rate>
            </plugin>
            <plugin name='GstCameraPlugin' filename='GstCameraPlugin'>
              <udp_host>127.0.0.1</udp_host>
              <udp_port>5600</udp_port>
              <use_basic_pipeline>true</use_basic_pipeline>
              <use_cuda>false</use_cuda>
            </plugin>
          </sensor>
        </link>
        <joint name='pitch_joint' type='revolute'>
          <parent>roll_link</parent>
          <child>pitch_link</child>
          <axis>
            <xyz>1 0 0</xyz>
            <dynamics>
              <damping>0.01</damping>
              <spring_reference>0</spring_reference>
              <spring_stiffness>0</spring_stiffness>
            </dynamics>
            <limit>
              <lower>-3.1415926000000001</lower>
              <upper>3.1415926000000001</upper>
            </limit>
          </axis>
          <pose>0.044999999999999998 0.0020999999999999999 0.019900000000000001 0 0 0</pose>
        </joint>
      </model>
      <joint name='gimbal_joint' type='revolute'>
        <parent>iris_with_standoffs::base_link</parent>
        <child>gimbal::base_link</child>
        <axis>
          <xyz>0 0 1</xyz>
          <limit>
            <lower>0</lower>
            <upper>0</upper>
            <effort>inf</effort>
            <velocity>inf</velocity>
            <stiffness>100000000</stiffness>
            <dissipation>1</dissipation>
          </limit>
          <dynamics>
            <spring_reference>0</spring_reference>
            <spring_stiffness>0</spring_stiffness>
            <damping>0</damping>
            <friction>0</friction>
          </dynamics>
        </axis>
        <pose>0 0 0 0 0 0</pose>
      </joint>
      <plugin name='gz::sim::systems::JointStatePublisher' filename='gz-sim-joint-state-publisher-system'/>
      <plugin name='gz::sim::systems::LiftDrag' filename='gz-sim-lift-drag-system'>
        <a0>0.3</a0>
        <alpha_stall>1.4</alpha_stall>
        <cla>4.2500</cla>
        <cda>0.10</cda>
        <cma>0.0</cma>
        <cla_stall>-0.025</cla_stall>
        <cda_stall>0.0</cda_stall>
        <cma_stall>0.0</cma_stall>
        <area>0.002</area>
        <air_density>1.2041</air_density>
        <cp>0.084 0 0</cp>
        <forward>0 1 0</forward>
        <upward>0 0 1</upward>
        <link_name>iris_with_standoffs::rotor_0</link_name>
      </plugin>
      <plugin name='gz::sim::systems::LiftDrag' filename='gz-sim-lift-drag-system'>
        <a0>0.3</a0>
        <alpha_stall>1.4</alpha_stall>
        <cla>4.2500</cla>
        <cda>0.10</cda>
        <cma>0.0</cma>
        <cla_stall>-0.025</cla_stall>
        <cda_stall>0.0</cda_stall>
        <cma_stall>0.0</cma_stall>
        <area>0.002</area>
        <air_density>1.2041</air_density>
        <cp>-0.084 0 0</cp>
        <forward>0 -1 0</forward>
        <upward>0 0 1</upward>
        <link_name>iris_with_standoffs::rotor_0</link_name>
      </plugin>
      <plugin name='gz::sim::systems::LiftDrag' filename='gz-sim-lift-drag-system'>
        <a0>0.3</a0>
        <alpha_stall>1.4</alpha_stall>
        <cla>4.2500</cla>
        <cda>0.10</cda>
        <cma>0.0</cma>
        <cla_stall>-0.025</cla_stall>
        <cda_stall>0.0</cda_stall>
        <cma_stall>0.0</cma_stall>
        <area>0.002</area>
        <air_density>1.2041</air_density>
        <cp>0.084 0 0</cp>
        <forward>0 1 0</forward>
        <upward>0 0 1</upward>
        <link_name>iris_with_standoffs::rotor_1</link_name>
      </plugin>
      <plugin name='gz::sim::systems::LiftDrag' filename='gz-sim-lift-drag-system'>
        <a0>0.3</a0>
        <alpha_stall>1.4</alpha_stall>
        <cla>4.2500</cla>
        <cda>0.10</cda>
        <cma>0.0</cma>
        <cla_stall>-0.025</cla_stall>
        <cda_stall>0.0</cda_stall>
        <cma_stall>0.0</cma_stall>
        <area>0.002</area>
        <air_density>1.2041</air_density>
        <cp>-0.084 0 0</cp>
        <forward>0 -1 0</forward>
        <upward>0 0 1</upward>
        <link_name>iris_with_standoffs::rotor_1</link_name>
      </plugin>
      <plugin name='gz::sim::systems::LiftDrag' filename='gz-sim-lift-drag-system'>
        <a0>0.3</a0>
        <alpha_stall>1.4</alpha_stall>
        <cla>4.2500</cla>
        <cda>0.10</cda>
        <cma>0.0</cma>
        <cla_stall>-0.025</cla_stall>
        <cda_stall>0.0</cda_stall>
        <cma_stall>0.0</cma_stall>
        <area>0.002</area>
        <air_density>1.2041</air_density>
        <cp>0.084 0 0</cp>
        <forward>0 -1 0</forward>
        <upward>0 0 1</upward>
        <link_name>iris_with_standoffs::rotor_2</link_name>
      </plugin>
      <plugin name='gz::sim::systems::LiftDrag' filename='gz-sim-lift-drag-system'>
        <a0>0.3</a0>
        <alpha_stall>1.4</alpha_stall>
        <cla>4.2500</cla>
        <cda>0.10</cda>
        <cma>0.0</cma>
        <cla_stall>-0.025</cla_stall>
        <cda_stall>0.0</cda_stall>
        <cma_stall>0.0</cma_stall>
        <area>0.002</area>
        <air_density>1.2041</air_density>
        <cp>-0.084 0 0</cp>
        <forward>0 1 0</forward>
        <upward>0 0 1</upward>
        <link_name>iris_with_standoffs::rotor_2</link_name>
      </plugin>
      <plugin name='gz::sim::systems::LiftDrag' filename='gz-sim-lift-drag-system'>
        <a0>0.3</a0>
        <alpha_stall>1.4</alpha_stall>
        <cla>4.2500</cla>
        <cda>0.10</cda>
        <cma>0.0</cma>
        <cla_stall>-0.025</cla_stall>
        <cda_stall>0.0</cda_stall>
        <cma_stall>0.0</cma_stall>
        <area>0.002</area>
        <air_density>1.2041</air_density>
        <cp>0.084 0 0</cp>
        <forward>0 -1 0</forward>
        <upward>0 0 1</upward>
        <link_name>iris_with_standoffs::rotor_3</link_name>
      </plugin>
      <plugin name='gz::sim::systems::LiftDrag' filename='gz-sim-lift-drag-system'>
        <a0>0.3</a0>
        <alpha_stall>1.4</alpha_stall>
        <cla>4.2500</cla>
        <cda>0.10</cda>
        <cma>0.0</cma>
        <cla_stall>-0.025</cla_stall>
        <cda_stall>0.0</cda_stall>
        <cma_stall>0.0</cma_stall>
        <area>0.002</area>
        <air_density>1.2041</air_density>
        <cp>-0.084 0 0</cp>
        <forward>0 1 0</forward>
        <upward>0 0 1</upward>
        <link_name>iris_with_standoffs::rotor_3</link_name>
      </plugin>
      <plugin name='gz::sim::systems::ApplyJointForce' filename='gz-sim-apply-joint-force-system'>
        <joint_name>iris_with_standoffs::rotor_0_joint</joint_name>
      </plugin>
      <plugin name='gz::sim::systems::ApplyJointForce' filename='gz-sim-apply-joint-force-system'>
        <joint_name>iris_with_standoffs::rotor_1_joint</joint_name>
      </plugin>
      <plugin name='gz::sim::systems::ApplyJointForce' filename='gz-sim-apply-joint-force-system'>
        <joint_name>iris_with_standoffs::rotor_2_joint</joint_name>
      </plugin>
      <plugin name='gz::sim::systems::ApplyJointForce' filename='gz-sim-apply-joint-force-system'>
        <joint_name>iris_with_standoffs::rotor_3_joint</joint_name>
      </plugin>
      <plugin name='ArduPilotPlugin' filename='ArduPilotPlugin'>
        <fdm_addr>127.0.0.1</fdm_addr>
        <fdm_port_in>9002</fdm_port_in>
        <fdm_port_out>9003</fdm_port_out>
        <connectionTimeoutMaxCount>5</connectionTimeoutMaxCount>
        <lock_step>1</lock_step>
        <modelXYZToAirplaneXForwardZDown degrees='true'>0 0 0 180 0 0</modelXYZToAirplaneXForwardZDown>
        <gazeboXYZToNED degrees='true'>0 0 0 180 0 90</gazeboXYZToNED>
        <imuName>iris_with_standoffs::imu_link::imu_sensor</imuName>
        <control channel='0'>
          <jointName>iris_with_standoffs::rotor_0_joint</jointName>
          <useForce>1</useForce>
          <multiplier>838</multiplier>
          <offset>0</offset>
          <servo_min>1100</servo_min>
          <servo_max>1900</servo_max>
          <type>VELOCITY</type>
          <p_gain>0.20</p_gain>
          <i_gain>0</i_gain>
          <d_gain>0</d_gain>
          <i_max>0</i_max>
          <i_min>0</i_min>
          <cmd_max>2.5</cmd_max>
          <cmd_min>-2.5</cmd_min>
          <controlVelocitySlowdownSim>1</controlVelocitySlowdownSim>
        </control>
        <control channel='1'>
          <jointName>iris_with_standoffs::rotor_1_joint</jointName>
          <useForce>1</useForce>
          <multiplier>838</multiplier>
          <offset>0</offset>
          <servo_min>1100</servo_min>
          <servo_max>1900</servo_max>
          <type>VELOCITY</type>
          <p_gain>0.20</p_gain>
          <i_gain>0</i_gain>
          <d_gain>0</d_gain>
          <i_max>0</i_max>
          <i_min>0</i_min>
          <cmd_max>2.5</cmd_max>
          <cmd_min>-2.5</cmd_min>
          <controlVelocitySlowdownSim>1</controlVelocitySlowdownSim>
        </control>
        <control channel='2'>
          <jointName>iris_with_standoffs::rotor_2_joint</jointName>
          <useForce>1</useForce>
          <multiplier>-838</multiplier>
          <offset>0</offset>
          <servo_min>1100</servo_min>
          <servo_max>1900</servo_max>
          <type>VELOCITY</type>
          <p_gain>0.20</p_gain>
          <i_gain>0</i_gain>
          <d_gain>0</d_gain>
          <i_max>0</i_max>
          <i_min>0</i_min>
          <cmd_max>2.5</cmd_max>
          <cmd_min>-2.5</cmd_min>
          <controlVelocitySlowdownSim>1</controlVelocitySlowdownSim>
        </control>
        <control channel='3'>
          <jointName>iris_with_standoffs::rotor_3_joint</jointName>
          <useForce>1</useForce>
          <multiplier>-838</multiplier>
          <offset>0</offset>
          <servo_min>1100</servo_min>
          <servo_max>1900</servo_max>
          <type>VELOCITY</type>
          <p_gain>0.20</p_gain>
          <i_gain>0</i_gain>
          <d_gain>0</d_gain>
          <i_max>0</i_max>
          <i_min>0</i_min>
          <cmd_max>2.5</cmd_max>
          <cmd_min>-2.5</cmd_min>
          <controlVelocitySlowdownSim>1</controlVelocitySlowdownSim>
        </control>
        <control channel='8'>
          <jointName>gimbal::roll_joint</jointName>
          <multiplier>1.047197551196</multiplier>
          <offset>-0.5</offset>
          <servo_min>1100</servo_min>
          <servo_max>1900</servo_max>
          <type>COMMAND</type>
          <cmd_topic>/gimbal/cmd_roll</cmd_topic>
          <p_gain>2</p_gain>
        </control>
        <control channel='9'>
          <jointName>gimbal::pitch_joint</jointName>
          <multiplier>-3.14159265</multiplier>
          <offset>-0.75</offset>
          <servo_min>1100</servo_min>
          <servo_max>1900</servo_max>
          <type>COMMAND</type>
          <cmd_topic>/gimbal/cmd_pitch</cmd_topic>
          <p_gain>2</p_gain>
        </control>
        <control channel='10'>
          <jointName>gimbal::yaw_joint</jointName>
          <multiplier>-5.5850536</multiplier>
          <offset>-0.5</offset>
          <servo_min>1100</servo_min>
          <servo_max>1900</servo_max>
          <type>COMMAND</type>
          <cmd_topic>/gimbal/cmd_yaw</cmd_topic>
          <p_gain>2</p_gain>
        </control>
      </plugin>
      <plugin name='gz::sim::systems::JointPositionController' filename='gz-sim-joint-position-controller-system'>
        <joint_name>gimbal::roll_joint</joint_name>
        <topic>/gimbal/cmd_roll</topic>
        <p_gain>2</p_gain>
      </plugin>
      <plugin name='gz::sim::systems::JointPositionController' filename='gz-sim-joint-position-controller-system'>
        <joint_name>gimbal::pitch_joint</joint_name>
        <topic>/gimbal/cmd_pitch</topic>
        <p_gain>2</p_gain>
      </plugin>
      <plugin name='gz::sim::systems::JointPositionController' filename='gz-sim-joint-position-controller-system'>
        <joint_name>gimbal::yaw_joint</joint_name>
        <topic>/gimbal/cmd_yaw</topic>
        <p_gain>2</p_gain>
      </plugin>
      <pose>-1.6699573301281308e-12 -6.8745871836164703e-12 0.19499941624585271 -8.5636950744657224e-12 -3.5254399178152713e-11 1.5707963267948943</pose>
      <static>false</static>
      <self_collide>false</self_collide>
    </model>
    <model name='untitled'>
      <link name='link'>
        <visual name='visual'>
          <geometry>
            <mesh>
              <uri>file:///home/aryan/Downloads/house_model/untitled.dae</uri>
            </mesh>
          </geometry>
        </visual>
        <collision name='collision'>
          <geometry>
            <mesh>
              <uri>file:///home/aryan/Downloads/house_model/untitled.dae</uri>
            </mesh>
          </geometry>
        </collision>
        <pose>0 0 0 0 0 0</pose>
        <inertial>
          <pose>0 0 0 0 0 0</pose>
          <mass>1</mass>
          <inertia>
            <ixx>1</ixx>
            <ixy>0</ixy>
            <ixz>0</ixz>
            <iyy>1</iyy>
            <iyz>0</iyz>
            <izz>1</izz>
          </inertia>
        </inertial>
        <enable_wind>false</enable_wind>
      </link>
      <pose>133.39105556045087 -69.481759985431438 -0.56458509238052068 -2.0859518572559376e-19 -5.8750721251021621e-19 -3.7523117055351441e-21</pose>
      <static>false</static>
      <self_collide>false</self_collide>
    </model>
    <model name='untitled_0'>
      <link name='link'>
        <visual name='visual'>
          <geometry>
            <mesh>
              <uri>file:///home/aryan/Downloads/house_model/untitled.dae</uri>
            </mesh>
          </geometry>
        </visual>
        <collision name='collision'>
          <geometry>
            <mesh>
              <uri>file:///home/aryan/Downloads/house_model/untitled.dae</uri>
            </mesh>
          </geometry>
        </collision>
        <pose>0 0 0 0 0 0</pose>
        <inertial>
          <pose>0 0 0 0 0 0</pose>
          <mass>1</mass>
          <inertia>
            <ixx>1</ixx>
            <ixy>0</ixy>
            <ixz>0</ixz>
            <iyy>1</iyy>
            <iyz>0</iyz>
            <izz>1</izz>
          </inertia>
        </inertial>
        <enable_wind>false</enable_wind>
      </link>
      <pose>-29.725698660075665 66.828327239187985 -0.56458509238052068 -4.7896229081346108e-19 -5.5722816156419161e-19 -3.1105944080049752e-21</pose>
      <static>false</static>
      <self_collide>false</self_collide>
    </model>
    <model name='untitled_1'>
      <link name='link'>
        <visual name='visual'>
          <geometry>
            <mesh>
              <uri>file:///home/aryan/Downloads/house_model/untitled.dae</uri>
            </mesh>
          </geometry>
        </visual>
        <collision name='collision'>
          <geometry>
            <mesh>
              <uri>file:///home/aryan/Downloads/house_model/untitled.dae</uri>
            </mesh>
          </geometry>
        </collision>
        <pose>0 0 0 0 0 0</pose>
        <inertial>
          <pose>0 0 0 0 0 0</pose>
          <mass>1</mass>
          <inertia>
            <ixx>1</ixx>
            <ixy>0</ixy>
            <ixz>0</ixz>
            <iyy>1</iyy>
            <iyz>0</iyz>
            <izz>1</izz>
          </inertia>
        </inertial>
        <enable_wind>false</enable_wind>
      </link>
      <pose>-24.17814826965332 -122.78700256347656 -0.56458583282886488 5.4348426874078852e-15 -7.0801297053149481e-18 3.0049099390887843e-19</pose>
      <static>false</static>
      <self_collide>false</self_collide>
    </model>
    <light name='sun' type='directional'>
      <pose>0 0 10 0 0 0</pose>
      <cast_shadows>true</cast_shadows>
      <intensity>1</intensity>
      <direction>-0.5 0.10000000000000001 -0.90000000000000002</direction>
      <diffuse>0.800000012 0.800000012 0.800000012 1</diffuse>
      <specular>0.800000012 0.800000012 0.800000012 1</specular>
      <attenuation>
        <range>1000</range>
        <linear>0.01</linear>
        <constant>0.90000000000000002</constant>
        <quadratic>0.001</quadratic>
      </attenuation>
      <spot>
        <inner_angle>0</inner_angle>
        <outer_angle>0</outer_angle>
        <falloff>0</falloff>
      </spot>
    </light>
  </world>
</sdf>
